<?xml version="1.0"?>
<robot xmlns:xacro="http://www.ros.org/wiki/xacro">

    <xacro:include filename="inertial_macros.xacro"/>

    <material name="white">
        <color rgba="1 1 1 1"/>
    </material>

    <material name="orange">
        <color rgba="1 0.3 0.1 1"/>
    </material>

    <material name="blue">
        <color rgba="0.2 0.2 1 1"/>
    </material>

    <material name="black">
        <color rgba="0 0 0 1"/>
    </material>

    <!-- BASE LINK -->
    <link name="base_link"/>
    
    <!-- CHASSIS LINK -->
    <joint name="chassis_joint" type="fixed">
        <parent link="base_link"/>
        <child link="chassis"/>
        <origin xyz="-0.04 0 0"/>
    </joint>

    <link name="chassis">
        <visual>
            <origin xyz="0.11 0 0.015"/>
            <geometry>
                <box size="0.22 0.22 0.03"/>
            </geometry>
            <material name="white"/>
        </visual>
        <collision>
            <origin xyz="0.11 0 0.015"/>
            <geometry>
                <box size="0.22 0.22 0.03"/>
            </geometry>
        </collision>
        <xacro:inertial_box mass="1.5" x="0.22" y="0.22" z="0.03">
            <origin xyz="0.11 0 0.015" rpy="0 0 0"/>
        </xacro:inertial_box>
    </link>

    <gazebo reference="chassis">
        <material>Gazebo/White</material>
    </gazebo>

    <!-- LEFT WHEEL LINK -->
    <joint name="left_wheel_joint" type="continuous">
        <parent link="base_link"/>
        <child link="left_wheel"/>
        <origin xyz="0 0.135 0" rpy="-${pi/2} 0 0"/>
        <axis xyz="0 0 1"/>
    </joint>

    <link name="left_wheel">
        <visual>
            <geometry>
                <cylinder radius="0.035" length="0.03"/>
            </geometry>
            <material name="blue"/>
        </visual>
        <collision>
            <geometry>
                <cylinder radius="0.035" length="0.03"/>
            </geometry>
        </collision>
        <xacro:inertial_cylinder mass="0.1" length="0.03" radius="0.035">
            <origin xyz="0 0 0" rpy="0 0 0"/>
        </xacro:inertial_cylinder>
    </link>
    
    <gazebo reference="left_wheel">
        <material>Gazebo/Blue</material>
    </gazebo>

    <transmission name="left_wheel_transmission">
        <type>transmission_interface/SimpleTransmission</type>
        <joint name="left_wheel_joint">
            <hardwareInterface>hardware_interface/VelocityJointInterface</hardwareInterface>
        </joint>
        <actuator name="left_wheel_actuator">
            <mechanicalReduction>7</mechanicalReduction>
            <hardwareInterface>VelocityJointInterface</hardwareInterface>
        </actuator>
    </transmission>

    <!-- RIGHT WHEEL LINK -->
    <joint name="right_wheel_joint" type="continuous">
        <parent link="base_link"/>
        <child link="right_wheel"/>
        <origin xyz="0 -0.135 0" rpy="${pi/2} 0 0"/>
        <axis xyz="0 0 -1"/>
    </joint>

    <link name="right_wheel">
        <visual>
            <geometry>
                <cylinder radius="0.035" length="0.03"/>
            </geometry>
            <material name="blue"/>
        </visual>
        <collision>
            <geometry>
                <cylinder radius="0.035" length="0.03"/>
            </geometry>
        </collision>
        <xacro:inertial_cylinder mass="0.1" length="0.03" radius="0.035">
            <origin xyz="0 0 0" rpy="0 0 0"/>
        </xacro:inertial_cylinder>
    </link>

    <gazebo reference="right_wheel">
        <material>Gazebo/Blue</material>
    </gazebo>

    <transmission name="right_wheel_transmission">
        <type>transmission_interface/SimpleTransmission</type>
        <joint name="right_wheel_joint">
            <hardwareInterface>hardware_interface/VelocityJointInterface</hardwareInterface>
        </joint>
        <actuator name="right_wheel_actuator">
            <mechanicalReduction>7</mechanicalReduction>
            <hardwareInterface>VelocityJointInterface</hardwareInterface>
        </actuator>
    </transmission>

    <!-- CASTER WHEEL LINK -->
    <joint name="caster_wheel_joint" type="fixed">
        <parent link="chassis"/>
        <child link="caster_wheel"/>
        <origin xyz="0.185 0 -0.010"/>
    </joint>

    <link name="caster_wheel">
        <visual>
            <geometry>
                <sphere radius="0.025"/>
            </geometry>
            <material name="black"/>
        </visual>
        <collision>
            <geometry>
                <sphere radius="0.025"/>
            </geometry>
        </collision>
        <xacro:inertial_sphere mass="0.1" radius="0.025">
            <origin xyz="0 0 0" rpy="0 0 0"/>
        </xacro:inertial_sphere>
    </link>

    <gazebo reference="caster_wheel">
        <material>Gazebo/Black</material>
        <mu1 value="0.001"/>
        <mu2 value="0.001"/>
    </gazebo>

    <!-- GAZEBO ROS CONTROL -->
    <gazebo>
        <plugin name="gazebo_ros_control" filename="libgazebo_ros_control.so"/>
    </gazebo>

    <!-- LIDAR SENSOR -->
    <joint name="lidar_joint" type="fixed">
        <parent link="chassis"/>
        <child link="lidar_link"/>
        <origin xyz="0.1 0 0.08" rpy="0 0 0"/>
    </joint>

    <link name="lidar_link">
        <visual>
            <origin xyz="0 0 0" rpy="0 0 0"/>
            <geometry>
                <cylinder radius="0.05" length="0.04"/>
            </geometry>
            <material name="black"/>
        </visual>
        <collision>
            <origin xyz="0 0 0" rpy="0 0 0"/>
            <geometry>
                <cylinder radius="0.05" length="0.04"/>
            </geometry>
        </collision>
        <inertial>
            <origin xyz="0 0 0" rpy="0 0 0"/>
            <mass value="0.3"/>
            <inertia ixx="0.001" ixy="0.0" ixz="0.0" iyy="0.001" iyz="0.0" izz="0.001"/>
        </inertial>
    </link>

    <gazebo reference="lidar_link">
        <sensor type="ray" name="lidar_sensor">
            <pose>0 0 0 0 0 0</pose>
            <visualize>true</visualize>
            <update_rate>10</update_rate>
            <ray>
                <scan>
                    <horizontal>
                        <samples>360</samples>
                        <resolution>1</resolution>
                        <min_angle>-3.1415</min_angle>
                        <max_angle>3.1415</max_angle>
                    </horizontal>
                </scan>
                <range>
                    <min>0.3</min>
                    <max>12</max>
                    <resolution>0.01</resolution>
                </range>
                <noise>
                    <type>gaussian</type>
                    <mean>0.0</mean>
                    <stddev>0.01</stddev>
                </noise>
            </ray>
            <plugin name="gazebo_ros_laser_controller" filename="libgazebo_ros_laser.so">
                <alwaysOn>true</alwaysOn>
                <updateRate>10.0</updateRate>
                <robotNamespace>/</robotNamespace>
                <frameName>lidar_link</frameName>
                <topicName>/scan</topicName>
            </plugin>
        </sensor>
    </gazebo>
</robot>

